// Below you can find the “rethrow” example. Rewrite it using async/await instead of .then/catch.

// And get rid of the recursion in favour of a loop in demoGithubUser: with async/await that becomes easy to do.

class HttpError extends Error {
  constructor(response) {
    super(`${response.status} for ${response.url}`);
    this.name = 'HttpError';
    this.response = response;
  }
}

async function loadJson(url) {
  let response = await fetch(url)
      if (response.status == 200) {
        let json = response.json();
        return json;
      } 
      
      throw new HttpError(response);
}

// Ask for a user name until github returns a valid user
async function demoGithubUser() {
  let user;
  while(true) {
    let name = prompt("Enter a name?", "iliakan");

    try {
      user = await loadJson(`https://api.github.com/users/${name}`)
      break;
    } catch(err) {
      if (err instanceof HttpError && err.response.status == 404) {
        alert("No such user, please reenter.");
      } else {
        throw err;
      }
    };
  }

  alert(`Full name: ${user.name}.`);
  return user;
}

demoGithubUser();